2013-10-15 22:47:55,223 - ubuntuone.SyncDaemon.Main - INFO - Starting Ubuntu One client version 4.2.0
2013-10-15 22:47:55,223 - ubuntuone.SyncDaemon.Main - INFO - Using '/home/mylinux/Ubuntu One' as root dir
2013-10-15 22:47:55,223 - ubuntuone.SyncDaemon.Main - INFO - Using '/home/mylinux/.local/share/ubuntuone/syncdaemon' as data dir
2013-10-15 22:47:55,223 - ubuntuone.SyncDaemon.Main - INFO - Using '/home/mylinux/.local/share/ubuntuone/shares' as shares root dir
2013-10-15 22:47:55,223 - ubuntuone.SyncDaemon.tritcask - INFO - Initializing Tritcask on: /home/mylinux/.local/share/ubuntuone/syncdaemon/tritcask
2013-10-15 22:47:55,225 - ubuntuone.SyncDaemon.tritcask - INFO - found 1 data files, 0 dead and 0 broken files
2013-10-15 22:47:55,237 - ubuntuone.SyncDaemon.tritcask - INFO - keydir ready! (keys: 2)
2013-10-15 22:47:55,247 - ubuntuone.SyncDaemon.fsm - INFO - loading updated metadata
2013-10-15 22:47:55,247 - ubuntuone.SyncDaemon.fsm - INFO - initialized: idx_path: 1, idx_node_id: 0, shares: 1
2013-10-15 22:47:55,275 - ubuntuone.SyncDaemon.filesystem_notifications.GeneralProcessor - INFO - Ignoring files: ['\\A#.*\\Z', '\\A.*~\\Z', '\\A.*\\.py[oc]\\Z', '\\A.*\\.sw[nopx]\\Z', '\\A.*\\.swpx\\Z', '\\A\\..*\\.tmp\\Z', '\\A\\.~lock\\..*#\\Z', '\\A.*\\.lock\\Z', '\\A\\.goutputstream-.*\\Z', '\\A.*-Spotlight\\Z', '\\A\\.DS_Store\\Z']
2013-10-15 22:47:55,302 - ubuntuone.SyncDaemon.TunnelRunner - INFO - Proxy support not installed.
2013-10-15 22:47:55,304 - ubuntuone.SyncDaemon.HQ - INFO - HashQueue: _hasher started
2013-10-15 22:47:55,876 - ubuntuone.SyncDaemon.DBus - INFO - DBusInterface initialized.
2013-10-15 22:47:56,305 - ubuntuone.SyncDaemon.InteractionInterfaces - INFO - connect: args (<ubuntuone.syncdaemon.interaction_interfaces.SyncdaemonService object at 0xa29c1cc>,), kwargs {'autoconnecting': True}.
2013-10-15 22:47:56,306 - ubuntuone.SyncDaemon.InteractionInterfaces - INFO - connect: result <generator object connect at 0x9f98194>.
2013-10-15 22:47:56,700 - ubuntuone.SyncDaemon.Main - NOTE - ---- MARK (state: <State: 'INIT'  (queues IDLE  connection 'Not User Not Network')>; queue: 0; offloaded: 0; hash: 0) ----
2013-10-15 22:47:56,701 - ubuntuone.SyncDaemon.Main - NOTE - Local rescan starting...
2013-10-15 22:47:56,701 - ubuntuone.SyncDaemon.local_rescan - INFO - start scan all volumes
2013-10-15 22:47:56,701 - ubuntuone.SyncDaemon.local_rescan - INFO - processing trash
2013-10-15 22:47:56,701 - ubuntuone.SyncDaemon.local_rescan - INFO - processing move limbo
2013-10-15 22:47:56,705 - ubuntuone.SyncDaemon.InteractionInterfaces - INFO - start: args (<ubuntuone.syncdaemon.interaction_interfaces.SyncdaemonService object at 0xa29c1cc>,), kwargs {}.
2013-10-15 22:47:56,706 - ubuntuone.SyncDaemon.InteractionInterfaces - INFO - start: result <Deferred at 0xa2adaec current result: None>.
2013-10-15 22:47:56,707 - ubuntuone.SyncDaemon - INFO - not starting twisted.manhole
2013-10-15 22:47:56,721 - ubuntuone.SyncDaemon.local_rescan - INFO - Ignoring path as it's a symlink: '/home/mylinux/Ubuntu One/Shared With Me'
2013-10-15 22:47:56,721 - ubuntuone.SyncDaemon.Main - NOTE - Local rescan finished!
2013-10-15 22:47:56,723 - ubuntuone.SyncDaemon.Main - INFO - hash queue empty. We are ready!
2013-10-15 22:47:58,033 - twisted - ERROR - Unhandled error in Deferred:
2013-10-15 22:47:58,058 - twisted - ERROR - Unhandled Error
Traceback (most recent call last):
  File "/usr/lib/python2.7/dist-packages/twisted/internet/defer.py", line 381, in callback
    self._startRunCallbacks(result)
  File "/usr/lib/python2.7/dist-packages/twisted/internet/defer.py", line 489, in _startRunCallbacks
    self._runCallbacks()
  File "/usr/lib/python2.7/dist-packages/twisted/internet/defer.py", line 576, in _runCallbacks
    current.result = callback(current.result, *args, **kw)
  File "/usr/lib/python2.7/dist-packages/twisted/internet/defer.py", line 1127, in gotResult
    _inlineCallbacks(r, g, deferred)
--- <exception caught here> ---
  File "/usr/lib/python2.7/dist-packages/twisted/internet/defer.py", line 1071, in _inlineCallbacks
    result = g.send(result)
  File "/usr/lib/python2.7/dist-packages/ubuntuone-client/ubuntuone/syncdaemon/interaction_interfaces.py", line 1273, in connect
    raise NoAccessToken("got empty credentials.")
ubuntuone.syncdaemon.interaction_interfaces.NoAccessToken: got empty credentials.

